Traceback (most recent call last):
  File "/usr/share/miniconda/lib/python3.10/site-packages/jupyter_cache/executors/utils.py", line 51, in single_nb_execution
    executenb(
  File "/usr/share/miniconda/lib/python3.10/site-packages/nbclient/client.py", line 1204, in execute
    return NotebookClient(nb=nb, resources=resources, km=km, **kwargs).execute()
  File "/usr/share/miniconda/lib/python3.10/site-packages/nbclient/util.py", line 84, in wrapped
    return just_run(coro(*args, **kwargs))
  File "/usr/share/miniconda/lib/python3.10/site-packages/nbclient/util.py", line 62, in just_run
    return loop.run_until_complete(coro)
  File "/usr/share/miniconda/lib/python3.10/asyncio/base_events.py", line 649, in run_until_complete
    return future.result()
  File "/usr/share/miniconda/lib/python3.10/site-packages/nbclient/client.py", line 663, in async_execute
    await self.async_execute_cell(
  File "/usr/share/miniconda/lib/python3.10/site-packages/nbclient/client.py", line 965, in async_execute_cell
    await self._check_raise_for_error(cell, cell_index, exec_reply)
  File "/usr/share/miniconda/lib/python3.10/site-packages/nbclient/client.py", line 862, in _check_raise_for_error
    raise CellExecutionError.from_cell_and_msg(cell, exec_reply_content)
nbclient.exceptions.CellExecutionError: An error occurred while executing the following cell:
------------------
# Displays name of current conda environment
from os import environ
print("You are using:", environ["CONDA_DEFAULT_ENV"])
------------------

[0;31m---------------------------------------------------------------------------[0m
[0;31mKeyError[0m                                  Traceback (most recent call last)
Cell [0;32mIn[1], line 3[0m
[1;32m      1[0m [38;5;66;03m# Displays name of current conda environment[39;00m
[1;32m      2[0m [38;5;28;01mfrom[39;00m [38;5;21;01mos[39;00m [38;5;28;01mimport[39;00m environ
[0;32m----> 3[0m [38;5;28mprint[39m([38;5;124m"[39m[38;5;124mYou are using:[39m[38;5;124m"[39m, [43menviron[49m[43m[[49m[38;5;124;43m"[39;49m[38;5;124;43mCONDA_DEFAULT_ENV[39;49m[38;5;124;43m"[39;49m[43m][49m)

File [0;32m/usr/share/miniconda/lib/python3.10/os.py:680[0m, in [0;36m_Environ.__getitem__[0;34m(self, key)[0m
[1;32m    677[0m     value [38;5;241m=[39m [38;5;28mself[39m[38;5;241m.[39m_data[[38;5;28mself[39m[38;5;241m.[39mencodekey(key)]
[1;32m    678[0m [38;5;28;01mexcept[39;00m [38;5;167;01mKeyError[39;00m:
[1;32m    679[0m     [38;5;66;03m# raise KeyError with the original key value[39;00m
[0;32m--> 680[0m     [38;5;28;01mraise[39;00m [38;5;167;01mKeyError[39;00m(key) [38;5;28;01mfrom[39;00m [38;5;28mNone[39m
[1;32m    681[0m [38;5;28;01mreturn[39;00m [38;5;28mself[39m[38;5;241m.[39mdecodevalue(value)

[0;31mKeyError[0m: 'CONDA_DEFAULT_ENV'
KeyError: 'CONDA_DEFAULT_ENV'

