Traceback (most recent call last):
  File "/usr/share/miniconda/lib/python3.10/site-packages/jupyter_cache/executors/utils.py", line 58, in single_nb_execution
    executenb(
  File "/usr/share/miniconda/lib/python3.10/site-packages/nbclient/client.py", line 1204, in execute
    return NotebookClient(nb=nb, resources=resources, km=km, **kwargs).execute()
  File "/usr/share/miniconda/lib/python3.10/site-packages/nbclient/util.py", line 84, in wrapped
    return just_run(coro(*args, **kwargs))
  File "/usr/share/miniconda/lib/python3.10/site-packages/nbclient/util.py", line 62, in just_run
    return loop.run_until_complete(coro)
  File "/usr/share/miniconda/lib/python3.10/asyncio/base_events.py", line 649, in run_until_complete
    return future.result()
  File "/usr/share/miniconda/lib/python3.10/site-packages/nbclient/client.py", line 663, in async_execute
    await self.async_execute_cell(
  File "/usr/share/miniconda/lib/python3.10/site-packages/nbclient/client.py", line 965, in async_execute_cell
    await self._check_raise_for_error(cell, cell_index, exec_reply)
  File "/usr/share/miniconda/lib/python3.10/site-packages/nbclient/client.py", line 862, in _check_raise_for_error
    raise CellExecutionError.from_cell_and_msg(cell, exec_reply_content)
nbclient.exceptions.CellExecutionError: An error occurred while executing the following cell:
------------------
for f in dl_tbl['Local Path']:
    filename = os.path.split(f)[-1]
    if not os.path.exists(filename):
        shutil.move(f, '.')
------------------

[0;31m---------------------------------------------------------------------------[0m
[0;31mFileNotFoundError[0m                         Traceback (most recent call last)
File [0;32m/usr/share/miniconda/lib/python3.10/shutil.py:816[0m, in [0;36mmove[0;34m(src, dst, copy_function)[0m
[1;32m    815[0m [38;5;28;01mtry[39;00m:
[0;32m--> 816[0m     [43mos[49m[38;5;241;43m.[39;49m[43mrename[49m[43m([49m[43msrc[49m[43m,[49m[43m [49m[43mreal_dst[49m[43m)[49m
[1;32m    817[0m [38;5;28;01mexcept[39;00m [38;5;167;01mOSError[39;00m:

[0;31mFileNotFoundError[0m: [Errno 2] No such file or directory: './mastDownload/HST/hst_14689_07_wfc3_uvis_f814w_id7307xf/hst_14689_07_wfc3_uvis_f814w_id7307xf_flc.fits' -> './hst_14689_07_wfc3_uvis_f814w_id7307xf_flc.fits'

During handling of the above exception, another exception occurred:

[0;31mFileNotFoundError[0m                         Traceback (most recent call last)
Cell [0;32mIn[5], line 4[0m
[1;32m      2[0m filename [38;5;241m=[39m os[38;5;241m.[39mpath[38;5;241m.[39msplit(f)[[38;5;241m-[39m[38;5;241m1[39m]
[1;32m      3[0m [38;5;28;01mif[39;00m [38;5;129;01mnot[39;00m os[38;5;241m.[39mpath[38;5;241m.[39mexists(filename):
[0;32m----> 4[0m     [43mshutil[49m[38;5;241;43m.[39;49m[43mmove[49m[43m([49m[43mf[49m[43m,[49m[43m [49m[38;5;124;43m'[39;49m[38;5;124;43m.[39;49m[38;5;124;43m'[39;49m[43m)[49m

File [0;32m/usr/share/miniconda/lib/python3.10/shutil.py:836[0m, in [0;36mmove[0;34m(src, dst, copy_function)[0m
[1;32m    834[0m         rmtree(src)
[1;32m    835[0m     [38;5;28;01melse[39;00m:
[0;32m--> 836[0m         [43mcopy_function[49m[43m([49m[43msrc[49m[43m,[49m[43m [49m[43mreal_dst[49m[43m)[49m
[1;32m    837[0m         os[38;5;241m.[39munlink(src)
[1;32m    838[0m [38;5;28;01mreturn[39;00m real_dst

File [0;32m/usr/share/miniconda/lib/python3.10/shutil.py:434[0m, in [0;36mcopy2[0;34m(src, dst, follow_symlinks)[0m
[1;32m    432[0m [38;5;28;01mif[39;00m os[38;5;241m.[39mpath[38;5;241m.[39misdir(dst):
[1;32m    433[0m     dst [38;5;241m=[39m os[38;5;241m.[39mpath[38;5;241m.[39mjoin(dst, os[38;5;241m.[39mpath[38;5;241m.[39mbasename(src))
[0;32m--> 434[0m [43mcopyfile[49m[43m([49m[43msrc[49m[43m,[49m[43m [49m[43mdst[49m[43m,[49m[43m [49m[43mfollow_symlinks[49m[38;5;241;43m=[39;49m[43mfollow_symlinks[49m[43m)[49m
[1;32m    435[0m copystat(src, dst, follow_symlinks[38;5;241m=[39mfollow_symlinks)
[1;32m    436[0m [38;5;28;01mreturn[39;00m dst

File [0;32m/usr/share/miniconda/lib/python3.10/shutil.py:254[0m, in [0;36mcopyfile[0;34m(src, dst, follow_symlinks)[0m
[1;32m    252[0m     os[38;5;241m.[39msymlink(os[38;5;241m.[39mreadlink(src), dst)
[1;32m    253[0m [38;5;28;01melse[39;00m:
[0;32m--> 254[0m     [38;5;28;01mwith[39;00m [38;5;28;43mopen[39;49m[43m([49m[43msrc[49m[43m,[49m[43m [49m[38;5;124;43m'[39;49m[38;5;124;43mrb[39;49m[38;5;124;43m'[39;49m[43m)[49m [38;5;28;01mas[39;00m fsrc:
[1;32m    255[0m         [38;5;28;01mtry[39;00m:
[1;32m    256[0m             [38;5;28;01mwith[39;00m [38;5;28mopen[39m(dst, [38;5;124m'[39m[38;5;124mwb[39m[38;5;124m'[39m) [38;5;28;01mas[39;00m fdst:
[1;32m    257[0m                 [38;5;66;03m# macOS[39;00m

[0;31mFileNotFoundError[0m: [Errno 2] No such file or directory: './mastDownload/HST/hst_14689_07_wfc3_uvis_f814w_id7307xf/hst_14689_07_wfc3_uvis_f814w_id7307xf_flc.fits'
FileNotFoundError: [Errno 2] No such file or directory: './mastDownload/HST/hst_14689_07_wfc3_uvis_f814w_id7307xf/hst_14689_07_wfc3_uvis_f814w_id7307xf_flc.fits'

